Workbook

Sheet Telemetry
A1: timestamp | B1: satellite_id | C1: position_x | D1: position_y | E1: position_z | F1: velocity_x | G1: velocity_y | H1: velocity_z | I1: semi_major_axis | J1: eccentricity | K1: inclination | L1: raan | M1: argument_of_perigee | N1: true_anomaly | O1: orientation_q0 | P1: orientation_q1 | Q1: orientation_q2 | R1: orientation_q3 | S1: angular_velocity_x | T1: angular_velocity_y | U1: angular_velocity_z | V1: battery_percentage | W1: battery_voltage | X1: battery_current | Y1: temperature | Z1: solar_power_input | AA1: power_draw | AB1: payload_status | AC1: payload_power_draw | AD1: communication_status | AE1: fuel_remaining_pct | AF1: sunlit
A2: 2019-12-09T00:00:00Z | B2: ISS-25544 | C2: 5008.0422 | D2: 4478.6159 | E2: -1058.7324 | F2: -3.8912014 | G2: 2.968865 | H2: -5.8857934 | I2: 6800.5855 | J2: 0.000789259 | K2: 51.662273 | L2: 214.64691 | M2: 92.388469 | N2: 99.05827 | O2: -0.019279924 | P2: -0.49515512 | Q2: -0.4207015 | R2: 0.75990784 | S2: -0.013021795 | T2: -0.063862632 | U2: -0.003162426 | V2: 58.855714 | W2: 7.4313484 | X2: -7.3910869 | Y2: 13.264689 | Z2: 0.30471708 | AA2: 55.230459 | AB2: ON | AC2: 24.480008 | AD2: LINKED | AE2: 100 | AF2: =FALSE() -> FALSE
A3: 2019-12-09T00:01:00Z | B3: ISS-25544 | C3: 4763.3194 | D3: 4646.3908 | E3: -1409.1872 | F3: -4.2631346 | G3: 2.6215351 | H3: -5.7915873 | I3: 6800.2211 | J3: 0.000717358 | K3: 51.66106 | L3: 214.64653 | M3: 86.861766 | N3: 108.45411 | O3: -0.033461877 | P3: -0.46921682 | Q3: -0.41981628 | R3: 0.77618952 | S3: 0.011272412 | T3: -0.062169472 | U3: -0.008592925 | V3: 57.700445 | W3: 7.4003665 | X3: -7.4932607 | Y3: 12.221264 | Z3: 0 | AA3: 55.452876 | AB3: ON | AC3: 24.573478 | AD3: LINKED | AE3: 100 | AF3: =FALSE() -> FALSE
A4: 2019-12-09T00:02:00Z | B4: ISS-25544 | C4: 4496.8592 | D4: 4792.962 | E4: -1753.1929 | F4: -4.6155085 | G4: 2.262344 | H4: -5.6709067 | I4: 6799.7632 | J4: 0.000671185 | K4: 51.659535 | L4: 214.64592 | M4: 79.050496 | N4: 120.13418 | O4: -0.047601582 | P4: -0.44274569 | Q4: -0.41845419 | R4: 0.79158476 | S4: -0.006809295 | T4: -0.058400828 | U4: -0.001545295 | V4: 56.241482 | W4: 7.348797 | X4: -9.529486 | Y4: 11.154742 | Z4: 0.36875078 | AA4: 70.399009 | AB4: ON | AC4: 24.520559 | AD4: DOWNLINKING | AE4: 100 | AF4: =FALSE() -> FALSE
A5: 2019-12-09T00:03:00Z | B5: ISS-25544 | C5: 4209.8837 | D5: 4917.6671 | E5: -2089.1775 | F5: -4.9467227 | G5: 1.8929418 | H5: -5.524321 | I5: 6799.2202 | J5: 0.000659992 | K5: 51.657724 | L5: 214.64502 | M5: 69.754853 | N5: 133.29837 | O5: -0.061683046 | P5: -0.41577192 | Q5: -0.41661682 | R5: 0.80607651 | S5: 0.00430821 | T5: -0.053813025 | U5: -0.00406415 | V5: 54.775727 | W5: 7.3219263 | X5: -9.6089798 | Y5: 10.320825 | Z5: 0 | AA5: 70.356242 | AB5: ON | AC5: 24.823933 | AD5: DOWNLINKING | AE5: 100 | AF5: =FALSE() -> FALSE
A6: 2019-12-09T00:04:00Z | B6: ISS-25544 | C6: 3903.7079 | D6: 5019.944 | E6: -2415.6067 | F6: -5.2552768 | G6: 1.5150226 | H6: -5.3525176 | I6: 6798.6021 | J6: 0.000687758 | K6: 51.655663 | L6: 214.64378 | M6: 60.552657 | N6: 146.36889 | O6: -0.075690374 | P6: -0.38832624 | Q6: -0.41430631 | R6: 0.81964869 | S6: -0.008401565 | T6: -0.068652468 | U6: 0.006505928 | V6: 53.313037 | W6: 7.3020923 | X6: -9.6149281 | Y6: 9.3705994 | Z6: 0 | AA6: 70.209093 | AB6: ON | AC6: 24.593114 | AD6: DOWNLINKING | AE6: 100 | AF6: =FALSE() -> FALSE
A7: 2019-12-09T00:05:00Z | B7: ISS-25544 | C7: 3579.7339 | D7: 5099.3334 | E7: -2730.991 | F7: -5.5397766 | G7: 1.1303167 | H7: -5.1562988 | I7: 6797.9202 | J7: 0.000750807 | K7: 51.653387 | L7: 214.64217 | M7: 52.932962 | N7: 157.85677 | O7: -0.089607786 | P7: -0.36043988 | Q7: -0.4115253 | R7: 0.83228629 | S7: 0.002186886 | T7: -0.060182629 | U7: 0.002235955 | V7: 51.878395 | W7: 7.2497247 | X7: -9.4986797 | Y7: 8.5370752 | Z7: 0.74325417 | AA7: 69.606067 | AB7: ON | AC7: 25.271577 | AD7: DOWNLINKING | AE7: 100 | AF7: =FALSE() -> FALSE
A8: 2019-12-09T00:06:00Z | B8: ISS-25544 | C8: 3239.4438 | D8: 5155.4809 | E8: -3033.8923 | F8: -5.7989405 | G8: 0.74058228 | H8: -4.936577 | I8: 6797.1868 | J8: 0.000840432 | K8: 51.650938 | L8: 214.64015 | M8: 47.537132 | N8: 167.12068 | O8: -0.10341964 | P8: -0.33214451 | Q8: -0.40827695 | R8: 0.84397532 | S8: -0.003196712 | T8: -0.06690208 | U8: -0.006388778 | V8: 50.427479 | W8: 7.2228853 | X8: -9.6421296 | Y8: 7.2730747 | Z8: 0.67891356 | AA8: 70.322909 | AB8: ON | AC8: 25.03379 | AD8: DOWNLINKING | AE8: 100 | AF8: =FALSE() -> FALSE
A9: 2019-12-09T00:07:00Z | B9: ISS-25544 | C9: 2884.3935 | D9: 5188.1379 | E9: -3322.9304 | F9: -6.0316044 | G9: 0.3475969 | H9: -4.6943705 | I9: 6796.4155 | J9: 0.000947155 | K9: 51.648362 | L9: 214.6377 | M9: 44.256302 | N9: 174.26954 | O9: -0.11711043 | P9: -0.30347224 | Q9: -0.40456493 | R9: 0.85470285 | S9: -0.00334885 | T9: -0.063747441 | U9: 0.005862223 | V9: 48.971611 | W9: 7.1946842 | X9: -9.7129543 | Y9: 6.00456 | Z9: 0 | AA9: 69.88164 | AB9: ON | AC9: 25.747471 | AD9: DOWNLINKING | AE9: 100 | AF9: =FALSE() -> FALSE
A10: 2019-12-09T00:08:00Z | B10: ISS-25544 | C10: 2516.2046 | D10: 5197.163 | E10: -3596.7894 | F10: -6.2367269 | G10: -0.046850388 | H10: -4.4307976 | I10: 6795.6202 | J10: 0.00106299 | K10: 51.645704 | L10: 214.6348 | M10: 42.679418 | N10: 179.71447 | O10: -0.13066482 | P10: -0.27445556 | Q10: -0.40039342 | R10: 0.86445703 | S10: -0.001913043 | T10: -0.070950972 | U10: -0.011332872 | V10: 47.839596 | W10: 7.1389033 | X10: -7.6113543 | Y10: 5.5617248 | Z10: 0.71122658 | AA10: 55.047949 | AB10: ON | AC10: 25.396674 | AD10: NO_CONTACT | AE10: 100 | AF10: =FALSE() -> FALSE
A11: 2019-12-09T00:09:00Z | B11: ISS-25544 | C11: 2136.5579 | D11: 5182.5223 | E11: -3854.2232 | F11: -6.4133931 | G11: -0.4409674 | H11: -4.1470718 | I11: 6794.8153 | J11: 0.001181786 | K11: 51.643014 | L11: 214.63144 | M11: 42.380251 | N11: 183.88173 | O11: -0.14406766 | P11: -0.24512731 | Q11: -0.39576711 | R11: 0.87322707 | S11: 0.001585397 | T11: -0.061456063 | U11: -0.003093465 | V11: 46.685617 | W11: 7.1342645 | X11: -7.7640808 | Y11: 4.7554628 | Z11: 0 | AA11: 55.391006 | AB11: ON | AC11: 25.24858 | AD11: NO_CONTACT | AE11: 100 | AF11: =FALSE() -> FALSE
A12: 2019-12-09T00:10:00Z | B12: ISS-25544 | C12: 1747.1848 | D12: 5144.2893 | E12: -4094.0611 | F12: -6.5608182 | G12: -0.83296683 | H12: -3.8444952 | I12: 6794.0155 | J12: 0.001298849 | K12: 51.640339 | L12: 214.62761 | M12: 43.012737 | N12: 187.11744 | O12: -0.15730398 | P12: -0.21552066 | Q12: -0.39069117 | R12: 0.88100324 | S12: 0.004869725 | T12: -0.066942431 | U12: 0.000124941 | V12: 45.563758 | W12: 7.0858954 | X12: -7.5994923 | Y12: 3.7589377 | Z12: 0.45677524 | AA12: 54.305983 | AB12: ON | AC12: 24.669037 | AD12: NO_CONTACT | AE12: 100 | AF12: =FALSE() -> FALSE
A13: 2019-12-09T00:11:00Z | B13: ISS-25544 | C13: 1349.86 | D13: 5082.6442 | E13: -4315.2134 | F13: -6.6783501 | G13: -1.2210742 | H13: -3.5244523 | I13: 6793.2353 | J13: 0.001410519 | K13: 51.63773 | L13: 214.62333 | M13: 44.318102 | N13: 189.68041 | O13: -0.17035902 | P13: -0.18566906 | Q13: -0.38517129 | R13: 0.88777693 | S13: -0.000797182 | T13: -0.07304322 | U13: -0.014471125 | V13: 44.409427 | W13: 7.0638565 | X13: -7.8438603 | Y13: 3.0440014 | Z13: 0.48074666 | AA13: 55.888651 | AB13: ON | AC13: 25.223266 | AD13: NO_CONTACT | AE13: 100 | AF13: =FALSE() -> FALSE
... A16: 2019-12-09T00:14:00Z | B16: ISS-25544 | C16: 128.40004 | D16: 4760.6203 | E16: -4856.9636 | F16: -6.8471009 | G16: -2.3446512 | H16: -2.4744742 | I16: 6791.1502 | J16: 0.00168643 | K16: 51.630755 | L16: 214.60795 | M16: 50.614915 | N16: 194.98981 | O16: -0.20829222 | P16: -0.094982593 | Q16: -0.36601197 | R16: 0.90201324 | S16: 0.000218521 | T16: -0.05662741 | U16: -0.002393556 | V16: 41.009479 | W16: 6.9736376 | X16: -7.793508 | Y16: 1.6757538 | Z16: 0 | AA16: 54.349101 | AB16: ON | AC16: 24.276971 | AD16: NO_CONTACT | AE16: 100 | AF16: =FALSE() -> FALSE
A17: 2019-12-09T00:15:00Z | B17: ISS-25544 | C17: -282.40545 | D17: 4609.2245 | E17: -4994.2449 | F17: -6.8412609 | G17: -2.699967 | H17: -2.0998327 | I17: 6790.5824 | J17: 0.001752076 | K17: 51.628855 | L17: 214.60208 | M17: 53.148446 | N17: 196.32552 | O17: -0.22047911 | P17: -0.064490185 | Q17: -0.3587827 | R17: 0.90471263 | S17: 0.003568711 | T17: -0.057327898 | U17: -0.011887631 | V17: 42.293226 | W17: 7.0422212 | X17: 8.7500621 | Y17: 2.9424995 | Z17: 116.92951 | AA17: 55.309635 | AB17: ON | AC17: 25.089638 | AD17: NO_CONTACT | AE17: 100 | AF17: =TRUE() -> TRUE
A18: 2019-12-09T00:16:00Z | B18: ISS-25544 | C18: -691.92692 | D18: 4436.8712 | E18: -5108.7528 | F18: -6.8043166 | G18: -3.0429732 | H18: -1.7156523 | I18: 6790.0963 | J18: 0.00180216 | K18: 51.62723 | L18: 214.5959 | M18: 55.776158 | N18: 197.56735 | O18: -0.23241443 | P18: -0.033923156 | Q18: -0.35114506 | R18: 0.90638287 | S18: -0.002222227 | T18: -0.072005385 | U18: -0.010155791 | V18: 43.625181 | W18: 7.0194706 | X18: 9.1080719 | Y18: 4.0859198 | Z18: 118.08075 | AA18: 54.146902 | AB18: ON | AC18: 24.536712 | AD18: NO_CONTACT | AE18: 100 | AF18: =TRUE() -> TRUE
A19: 2019-12-09T00:17:00Z | B19: ISS-25544 | C19: -1098.3026 | D19: 4244.3457 | E19: -5199.9672 | F19: -6.7364389 | G19: -3.3721265 | H19: -1.3236696 | I19: 6789.7008 | J19: 0.00183574 | K19: 51.625907 | L19: 214.58947 | M19: 58.442465 | N19: 198.77089 | O19: -0.24408494 | P19: -0.003315958 | Q19: -0.34310753 | R19: 0.90702192 | S19: -0.009895381 | T19: -0.075317234 | U19: 0.002677115 | V19: 44.948614 | W19: 7.137044 | X19: 8.9007084 | Y19: 5.1059467 | Z19: 120.94054 | AA19: 57.415794 | AB19: ON | AC19: 25.419063 | AD19: NO_CONTACT | AE19: 100 | AF19: =TRUE() -> TRUE
A20: 2019-12-09T00:18:00Z | B20: ISS-25544 | C20: -1499.6849 | D20: 4032.5237 | E20: -5267.4726 | F20: -6.6379353 | G20: -3.6859461 | H20: -0.92565504 | I20: 6789.4031 | J20: 0.001852195 | K20: 51.624912 | L20: 214.58284 | M20: 61.097105 | N20: 199.98644 | O20: -0.25547765 | P20: 0.027296912 | Q20: -0.33467909 | R20: 0.9066289 | S20: 0.001570486 | T20: -0.06545443 | U20: -0.010356538 | V20: 46.26905 | W20: 7.1076414 | X20: 8.9172974 | Y20: 6.2704434 | Z20: 117.56118 | AA20: 54.180225 | AB20: ON | AC20: 24.792321 | AD20: NO_CONTACT | AE20: 100 | AF20: =TRUE() -> TRUE
A21: 2019-12-09T00:19:00Z | B21: ISS-25544 | C21: -1894.249 | D21: 3802.3682 | E21: -5310.9611 | F21: -6.5092484 | G21: -3.983019 | H21: -0.52340496 | I21: 6789.2085 | J21: 0.001851241 | K21: 51.624263 | L21: 214.57606 | M21: 63.691512 | N21: 201.26257 | O21: -0.26657988 | P21: 0.057880936 | Q21: -0.32586912 | R21: 0.905204 | S21: 0.009827395 | T21: -0.067160513 | U21: -0.011849438 | V21: 47.524735 | W21: 7.1759522 | X21: 8.3992877 | Y21: 7.0960036 | Z21: 114.97595 | AA21: 54.703063 | AB21: ON | AC21: 24.756846 | AD21: NO_CONTACT | AE21: 100 | AF21: =TRUE() -> TRUE
A22: 2019-12-09T00:20:00Z | B22: ISS-25544 | C22: -2280.2005 | D22: 3554.9244 | E22: -5330.2328 | F22: -6.3509536 | G22: -4.2620063 | H22: -0.11873439 | I22: 6789.1207 | J22: 0.001832944 | K22: 51.623971 | L22: 214.56921 | M22: 66.175532 | N22: 202.64944 | O22: -0.27737927 | P22: 0.088401612 | Q22: -0.31668746 | R22: 0.90274855 | S22: -0.009029272 | T22: -0.060007424 | U22: 0.00384951 | V22: 48.781793 | W22: 7.1543353 | X22: 8.4338783 | Y22: 8.0927502 | Z22: 117.10465 | AA22: 56.765857 | AB22: ON | AC22: 24.637387 | AD22: NO_CONTACT | AE22: 100 | AF22: =TRUE() -> TRUE
A23: 2019-12-09T00:21:00Z | B23: ISS-25544 | C23: -2655.7833 | D23: 3291.3157 | E23: -5325.1973 | F23: -6.1637569 | G23: -4.5216485 | H23: 0.28653062 | I23: 6789.1412 | J23: 0.001797738 | K23: 51.624043 | L23: 214.56233 | M23: 68.494087 | N23: 204.20216 | O23: -0.28786378 | P23: 0.11882449 | Q23: -0.30714436 | R23: 0.899265 | S23: -0.012256058 | T23: -0.071054684 | U23: 0.001725879 | V23: 50.140236 | W23: 7.2122871 | X23: 9.0408568 | Y23: 8.6516176 | Z23: 119.53009 | AA23: 54.324831 | AB23: ON | AC23: 24.979619 | AD23: NO_CONTACT | AE23: 100 | AF23: =TRUE() -> TRUE
A24: 2019-12-09T00:22:00Z | B24: ISS-25544 | C24: -3019.2879 | D24: 3012.7384 | E24: -5295.8738 | F24: -5.9484922 | G24: -4.7607708 | H24: 0.69056046 | I24: 6789.2698 | J24: 0.001746455 | K24: 51.624476 | L24: 214.5555 | M24: 70.583468 | N24: 205.98442 | O24: -0.29802168 | P24: 0.14911519 | Q24: -0.29725047 | R24: 0.89475689 | S24: 0.002193825 | T24: -0.066717795 | U24: 0.011062887 | V24: 51.593901 | W24: 7.2439702 | X24: 9.6322755 | Y24: 9.7108373 | Z24: 124.73727 | AA24: 54.961357 | AB24: ON | AC24: 25.079996 | AD24: NO_CONTACT | AE24: 100 | AF24: =TRUE() -> TRUE
A25: 2019-12-09T00:23:00Z | B25: ISS-25544 | C25: -3369.0583 | D25: 2720.4569 | E25: -5242.3913 | F25: -5.7061179 | G25: -4.9782879 | H25: 1.0915296 | I25: 6789.5042 | J25: 0.001680369 | K25: 51.625263 | L25: 214.54878 | M25: 72.366916 | N25: 208.07301 | O25: -0.30784162 | P25: 0.17923947 | Q25: -0.28701689 | R25: 0.88922891 | S25: 0.016509279 | T25: -0.056041482 | U25: -0.001795192 | V25: 52.95505 | W25: 7.2464318 | X25: 9.0161832 | Y25: 9.9148476 | Z25: 121.28627 | AA25: 55.951112 | AB25: ON | AC25: 25.767878 | AD25: NO_CONTACT | AE25: 100 | AF25: =TRUE() -> TRUE
A26: 2019-12-09T00:24:00Z | B26: ISS-25544 | C26: -3703.4996 | D26: 2415.7975 | E26: -5164.9878 | F26: -5.4377131 | G26: -5.1732089 | H26: 1.487624 | I26: 6789.8402 | J26: 0.001601252 | K26: 51.626391 | L26: 214.54222 | M26: 73.749237 | N26: 210.56311 | O26: -0.31731257 | P26: 0.20916322 | Q26: -0.27645507 | R26: 0.88268685 | S26: -0.003946051 | T26: -0.06468062 | U26: -0.001634429 | V26: 54.293108 | W26: 7.28514 | X26: 8.8161327 | Y26: 10.712103 | Z26: 118.85044 | AA26: 54.623676 | AB26: ON | AC26: 25.730722 | AD26: NO_CONTACT | AE26: 100 | AF26: =TRUE() -> TRUE
A27: 2019-12-09T00:25:00Z | B27: ISS-25544 | C27: -4021.0854 | D27: 2100.1433 | E27: -5064.0099 | F27: -5.1444735 | G27: -5.3446416 | H27: 1.877049 | I27: 6790.2718 | J27: 0.00151146 | K27: 51.627837 | L27: 214.53588 | M27: 74.61042 | N27: 213.57476 | O27: -0.32642388 | P27: 0.2388525 | Q27: -0.26557687 | R27: 0.87513762 | S27: -0.000487184 | T27: -0.068864998 | U27: -0.012188131 | V27: 55.651824 | W27: 7.3485226 | X27: 8.8750354 | Y27: 10.661447 | Z27: 121.01272 | AA27: 55.794326 | AB27: ON | AC27: 25.703741 | AD27: NO_CONTACT | AE27: 100 | AF27: =TRUE() -> TRUE
A28: 2019-12-09T00:26:00Z | B28: ISS-25544 | C28: -4320.3642 | D28: 1774.9279 | E28: -4939.9109 | F28: -4.8277071 | G28: -5.4917965 | H28: 2.2580369 | I28: 6790.7912 | J28: 0.001414061 | K28: 51.629577 | L28: 214.52981 | M28: 74.79894 | N28: 217.25946 | O28: -0.33516528 | P28: 0.26827362 | Q28: -0.25439454 | R28: 0.86658925 | S28: -0.004841694 | T28: -0.066279796 | U28: 0.010027578 | V28: 56.935506 | W28: 7.3399243 | X28: 8.3947327 | Y28: 11.237564 | Z28: 117.36554 | AA28: 55.748841 | AB28: ON | AC28: 24.832938 | AD28: NO_CONTACT | AE28: 100 | AF28: =TRUE() -> TRUE
... A77: 2019-12-09T01:15:00Z | B77: ISS-25544 | C77: 5007.6247 | D77: -890.67427 | E77: 4498.8846 | F77: 3.9181788 | G77: 5.7523424 | H77: -3.2058253 | I77: 6792.5231 | J77: 0.001468541 | K77: 51.635357 | L77: 214.35587 | M77: 44.519651 | N77: 77.809639 | O77: -0.22385059 | P77: 0.83965682 | Q77: 0.35530875 | R77: -0.34441695 | S77: 0.005411316 | T77: -0.060802077 | U77: 0.004480994 | V77: 100 | W77: 8.3874482 | X77: 10.201023 | Y77: 20.910264 | Z77: 121.54623 | AA77: 35.985678 | AB77: STANDBY | AC77: 4.7112306 | AD77: NO_CONTACT | AE77: 100 | AF77: =TRUE() -> TRUE
A78: 2019-12-09T01:16:00Z | B78: ISS-25544 | C78: 5231.0853 | D78: -543.76034 | E78: 4296.3655 | F78: 3.527666 | G78: 5.8070528 | H78: -3.5422454 | I78: 6793.2769 | J78: 0.001516643 | K78: 51.637869 | L78: 214.35116 | M78: 48.47279 | N78: 77.738561 | O78: -0.21168335 | P78: 0.82753266 | Q78: 0.36264881 | R78: -0.37264689 | S78: 0.004463221 | T78: -0.068638948 | U78: -0.012826347 | V78: 99.286777 | W78: 8.3875882 | X78: -4.0815916 | Y78: 19.03763 | Z78: 0 | AA78: 34.234709 | AB78: STANDBY | AC78: 5.2690172 | AD78: NO_CONTACT | AE78: 100 | AF78: =FALSE() -> FALSE
A79: 2019-12-09T01:17:00Z | B79: ISS-25544 | C79: 5430.6222 | D79: -194.35958 | E79: 4074.1412 | F79: 3.1210266 | G79: 5.8352047 | H79: -3.8624133 | I79: 6794.0637 | J79: 0.001554809 | K79: 51.640492 | L79: 214.34691 | M79: 52.579194 | N79: 77.513384 | O79: -0.19927605 | P79: 0.81446153 | Q79: 0.36957392 | R79: -0.40044548 | S79: 0.000321077 | T79: -0.063250164 | U79: -0.006196659 | V79: 98.582756 | W79: 8.3950097 | X79: -4.0253706 | Y79: 17.553553 | Z79: 0.71382014 | AA79: 34.506845 | AB79: STANDBY | AC79: 5.1208223 | AD79: NO_CONTACT | AE79: 100 | AF79: =FALSE() -> FALSE
A80: 2019-12-09T01:18:00Z | B80: ISS-25544 | C80: 5605.3233 | D80: 155.93005 | E80: 3833.2313 | F80: 2.7001199 | G80: 5.8366702 | H80: -4.164862 | I80: 6794.869 | J80: 0.001582495 | K80: 51.643177 | L80: 214.34311 | M80: 56.785216 | N80: 77.187736 | O80: -0.18664318 | P80: 0.8004588 | Q80: 0.37607643 | R80: -0.42778096 | S80: -0.024127803 | T80: -0.056528564 | U80: 0.02549328 | V80: 97.877537 | W80: 8.3763137 | X80: -4.0412167 | Y80: 15.9637 | Z80: 0.47113629 | AA80: 34.321635 | AB80: STANDBY | AC80: 4.7332738 | AD80: NO_CONTACT | AE80: 100 | AF80: =FALSE() -> FALSE
A81: 2019-12-09T01:19:00Z | B81: ISS-25544 | C81: 5754.39 | D81: 505.50659 | E81: 3574.7408 | F81: 2.2668717 | G81: 5.8114435 | H81: -4.4482045 | I81: 6795.678 | J81: 0.001599261 | K81: 51.645875 | L81: 214.33977 | M81: 61.043764 | N81: 76.808692 | O81: -0.17379945 | P81: 0.78554086 | Q81: 0.38214915 | R81: -0.45462218 | S81: -0.01113388 | T81: -0.061673911 | U81: 0.005245074 | V81: 97.175014 | W81: 8.3264759 | X81: -4.0498643 | Y81: 14.708537 | Z81: 0 | AA81: 33.721097 | AB81: STANDBY | AC81: 4.031581 | AD81: NO_CONTACT | AE81: 100 | AF81: =FALSE() -> FALSE
A82: 2019-12-09T01:20:00Z | B82: ISS-25544 | C82: 5877.1411 | D82: 852.77135 | E82: 3299.8557 | F82: 1.8232654 | G82: 5.7596409 | H82: -4.7111409 | I82: 6796.4759 | J82: 0.00160476 | K82: 51.648536 | L82: 214.3369 | M82: 65.311814 | N82: 76.419273 | O82: -0.16075982 | P82: 0.76972517 | Q82: 0.38778541 | R82: -0.48093858 | S82: -0.001420032 | T82: -0.061484063 | U82: -0.017306716 | V82: 96.3958 | W82: 8.3169384 | X82: -4.4971216 | Y82: 13.471913 | Z82: 0 | AA82: 37.402283 | AB82: STANDBY | AC82: 5.3495984 | AD82: NO_CONTACT | AE82: 100 | AF82: =FALSE() -> FALSE
A83: 2019-12-09T01:21:00Z | B83: ISS-25544 | C83: 5973.0157 | D83: 1196.1363 | E83: 3009.8369 | F83: 1.3713334 | G83: 5.6815011 | H83: -4.9524644 | I83: 6797.248 | J83: 0.001598743 | K83: 51.651111 | L83: 214.33448 | M83: 69.548265 | N83: 76.060577 | O83: -0.14753943 | P83: 0.75303019 | Q83: 0.39297902 | R83: -0.50670025 | S83: -0.011037407 | T83: -0.06161305 | U83: 0.003194003 | V83: 95.635629 | W83: 8.2917716 | X83: -4.4005315 | Y83: 12.898684 | Z83: 0.1643907 | AA83: 36.652593 | AB83: STANDBY | AC83: 4.804768 | AD83: NO_CONTACT | AE83: 100 | AF83: =FALSE() -> FALSE
A84: 2019-12-09T01:22:00Z | B84: ISS-25544 | C84: 6041.5764 | D84: 1534.0315 | E84: 2706.0151 | F84: 0.91314749 | G84: 5.5773837 | H84: -5.1710673 | I84: 6797.9804 | J84: 0.001581062 | K84: 51.653555 | L84: 214.3325 | M84: 73.711918 | N84: 75.773812 | O84: -0.13415366 | P84: 0.73547538 | Q84: 0.39772429 | R84: -0.53187795 | S84: -0.000175628 | T84: -0.06905103 | U84: -0.003423409 | V84: 94.879353 | W84: 8.2706286 | X84: -4.3891726 | Y84: 11.346161 | Z84: 0 | AA84: 36.301217 | AB84: STANDBY | AC84: 5.0886981 | AD84: NO_CONTACT | AE84: 100 | AF84: =FALSE() -> FALSE
A85: 2019-12-09T01:23:00Z | B85: ISS-25544 | C85: 6082.5109 | D85: 1864.9119 | E85: 2389.784 | F85: 0.45080938 | G85: 5.4477688 | H85: -5.3659463 | I85: 6798.6595 | J85: 0.001551687 | K85: 51.655821 | L85: 214.33092 | M85: 77.759325 | N85: 75.60244 | O85: -0.12061802 | P85: 0.71708117 | Q85: 0.40201602 | R85: -0.55644317 | S85: -0.025647443 | T85: -0.060605024 | U85: 0.002723698 | V85: 94.201614 | W85: 8.2704801 | X85: -3.9334495 | Y85: 10.222037 | Z85: 0 | AA85: 32.531516 | AB85: STANDBY | AC85: 4.1471739 | AD85: NO_CONTACT | AE85: 100 | AF85: =FALSE() -> FALSE
A86: 2019-12-09T01:24:00Z | B86: ISS-25544 | C86: 6095.6335 | D86: 2187.2652 | E86: 2062.5946 | F86: -0.013559197 | G86: 5.2932538 | H86: -5.5362075 | I86: 6799.2731 | J86: 0.001510726 | K86: 51.657869 | L86: 214.32972 | M86: 81.642265 | N86: 75.594699 | O86: -0.10694818 | P86: 0.69786894 | Q86: 0.40584956 | R86: -0.58036812 | S86: 0.004201886 | T86: -0.062581995 | U86: -0.001669279 | V86: 93.468751 | W86: 8.250237 | X86: -4.2638039 | Y86: 10.025716 | Z86: 0 | AA86: 35.177393 | AB86: STANDBY | AC86: 4.3415849 | AD86: NO_CONTACT | AE86: 100 | AF86: =FALSE() -> FALSE
A87: 2019-12-09T01:25:00Z | B87: ISS-25544 | C87: 6080.8864 | D87: 2499.618 | E87: 1725.9477 | F87: -0.47782651 | G87: 5.1145518 | H87: -5.681071 | I87: 6799.8098 | J87: 0.001458461 | K87: 51.659662 | L87: 214.32884 | M87: 85.304532 | N87: 75.806824 | O87: -0.093159951 | P87: 0.67786098 | Q87: 0.40922075 | R87: -0.60362579 | S87: -0.004791032 | T87: -0.060558863 | U87: 0.014983744 | V87: 92.724012 | W87: 8.2149498 | X87: -4.3515167 | Y87: 8.9938078 | Z87: 0.81677587 | AA87: 36.564268 | AB87: STANDBY | AC87: 5.3125426 | AD87: NO_CONTACT | AE87: 100 | AF87: =FALSE() -> FALSE
A88: 2019-12-09T01:26:00Z | B88: ISS-25544 | C88: 6038.3397 | D88: 2800.5435 | E88: 1381.3879 | F88: -0.93986092 | G88: 4.912488 | H88: -5.7998746 | I88: 6800.26 | J88: 0.001395379 | K88: 51.661166 | L88: 214.32825 | M88: 88.677591 | N88: 76.307382 | O88: -0.079269245 | P88: 0.65708045 | Q88: 0.41212593 | R88: -0.62618997 | S88: -0.022517773 | T88: -0.068639991 | U88: -0.007824163 | V88: 91.992727 | W88: 8.2029102 | X88: -4.2791753 | Y88: 8.4297335 | Z88: 0 | AA88: 35.10169 | AB88: STANDBY | AC88: 4.7876131 | AD88: NO_CONTACT | AE88: 100 | AF88: =FALSE() -> FALSE
A89: 2019-12-09T01:27:00Z | B89: ISS-25544 | C89: 5968.1909 | D89: 3088.6672 | E89: 1030.4955 | F89: -1.3975412 | G89: 4.6879956 | H89: -5.8920771 | I89: 6800.6154 | J89: 0.001322238 | K89: 51.662355 | L89: 214.3279 | M89: 91.67449 | N89: 77.18336 | O89: 0.065292063 | P89: -0.63555139 | Q89: -0.414562 | R89: 0.64803528 | S89: -0.002450607 | T89: -0.069655477 | U89: -0.000569545 | V89: 91.292664 | W89: 8.1870018 | X89: -4.104436 | Y89: 7.9421366 | Z89: 0 | AA89: 33.603025 | AB89: STANDBY | AC89: 4.5181808 | AD89: NO_CONTACT | AE89: 100 | AF89: =FALSE() -> FALSE
... A108: 2019-12-09T01:46:00Z | B108: ISS-25544 | C108: 498.53536 | D108: 4867.8793 | E108: -4725.2135 | F108: -6.8393429 | G108: -2.0012672 | H108: -2.7790514 | I108: 6791.6793 | J108: 0.001622224 | K108: 51.632528 | L108: 214.29304 | M108: 48.707352 | N108: 193.66371 | O108: -0.19541575 | P108: -0.12142182 | Q108: -0.37139782 | R108: 0.89951825 | S108: 0.000310856 | T108: -0.063235872 | U108: 0.000139852 | V108: 70.4932 | W108: 7.6820418 | X108: -7.1755228 | Y108: -1.4658582 | Z108: 0 | AA108: 55.122666 | AB108: ON | AC108: 25.484499 | AD108: NO_CONTACT | AE108: 100 | AF108: =FALSE() -> FALSE
...

Sheet Channel_Anomalies
A1: timestamp | B1: satellite_id | C1: temperature_anomaly | D1: battery_voltage_anomaly | E1: solar_power_anomaly
A2: 2019-12-09T00:00:00Z | B2: ISS-25544 | C2: 0 | D2: 0 | E2: 0
A3: 2019-12-09T00:01:00Z | B3: ISS-25544 | C3: 0 | D3: 0 | E3: 0
A4: 2019-12-09T00:02:00Z | B4: ISS-25544 | C4: 0 | D4: 0 | E4: 0
A5: 2019-12-09T00:03:00Z | B5: ISS-25544 | C5: 0 | D5: 0 | E5: 0
A6: 2019-12-09T00:04:00Z | B6: ISS-25544 | C6: 0 | D6: 0 | E6: 0
A7: 2019-12-09T00:05:00Z | B7: ISS-25544 | C7: 0 | D7: 0 | E7: 0
A8: 2019-12-09T00:06:00Z | B8: ISS-25544 | C8: 0 | D8: 0 | E8: 0
A9: 2019-12-09T00:07:00Z | B9: ISS-25544 | C9: 0 | D9: 0 | E9: 0
A10: 2019-12-09T00:08:00Z | B10: ISS-25544 | C10: 0 | D10: 0 | E10: 0
A11: 2019-12-09T00:09:00Z | B11: ISS-25544 | C11: 0 | D11: 0 | E11: 0
A12: 2019-12-09T00:10:00Z | B12: ISS-25544 | C12: 0 | D12: 0 | E12: 0
A13: 2019-12-09T00:11:00Z | B13: ISS-25544 | C13: 0 | D13: 0 | E13: 0
... A4321: 2019-12-11T23:59:00Z | B4321: ISS-25544 | C4321: 0 | D4321: 0 | E4321: 0

Sheet Twin_Derived
A1: timestamp | B1: satellite_id | C1: battery_health | D1: thermal_health | E1: power_health | F1: payload_health | G1: anomaly_flag | H1: anomaly_parameter | I1: anomaly_confidence | J1: health_score | K1: risk_level | L1: twin_state_id | M1: source_row_index | N1: sync_status | O1: state_confidence
A2: =Telemetry!A2 -> 2019-12-09T00:00:00Z | B2: =Telemetry!B2 -> ISS-25544 | C2: =Telemetry!V2 -> 58.855714 | D2: =MAX(0,MIN(100,100-ABS(Telemetry!Y2-20)*3)) -> 79.794068 | E2: =MAX(0,MIN(100,100-ABS(Telemetry!AA2-90)*1.2)) -> 58.276551 | F2: =IF(Telemetry!AB2="ON",95,100) -> 95 | G2: =IF(OR(Channel_Anomalies!C2=1,Channel_Anomalies!D2=1,Channel_Anomalies!E2=1),1,0) -> 0 | H2: =IF(Channel_Anomalies!C2=1,"temperature",IF(Channel_Anomalies!D2=1,"battery_voltage",IF(Channel_Anomalies!E2=1,"solar_power_input",""))) | I2: =IF(Channel_Anomalies!C2=1,0.9,IF(Channel_Anomalies!D2=1,0.85,IF(Channel_Anomalies!E2=1,0.75,0))) -> 0 | J2: =MAX(0,MIN(100,0.35*C2+0.25*D2+0.25*E2+0.15*F2-IF(G2=1,12,0))) -> 69.367155 | K2: =IF(J2<40,"CRITICAL",IF(J2<60,"HIGH",IF(J2<80,"MED","LOW"))) -> MED | L2: ="TWIN-"&TEXT(M2,"000000") -> TWIN-000000 | M2: =ROW()-2 -> 0 | N2: LIVE_REPLAY | O2: 1
A3: =Telemetry!A3 -> 2019-12-09T00:01:00Z | B3: =Telemetry!B3 -> ISS-25544 | C3: =Telemetry!V3 -> 57.700445 | D3: =MAX(0,MIN(100,100-ABS(Telemetry!Y3-20)*3)) -> 76.663793 | E3: =MAX(0,MIN(100,100-ABS(Telemetry!AA3-90)*1.2)) -> 58.543451 | F3: =IF(Telemetry!AB3="ON",95,100) -> 95 | G3: =IF(OR(Channel_Anomalies!C3=1,Channel_Anomalies!D3=1,Channel_Anomalies!E3=1),1,0) -> 0 | H3: =IF(Channel_Anomalies!C3=1,"temperature",IF(Channel_Anomalies!D3=1,"battery_voltage",IF(Channel_Anomalies!E3=1,"solar_power_input",""))) | I3: =IF(Channel_Anomalies!C3=1,0.9,IF(Channel_Anomalies!D3=1,0.85,IF(Channel_Anomalies!E3=1,0.75,0))) -> 0 | J3: =MAX(0,MIN(100,0.35*C3+0.25*D3+0.25*E3+0.15*F3-IF(G3=1,12,0))) -> 68.246967 | K3: =IF(J3<40,"CRITICAL",IF(J3<60,"HIGH",IF(J3<80,"MED","LOW"))) -> MED | L3: ="TWIN-"&TEXT(M3,"000000") -> TWIN-000001 | M3: =ROW()-2 -> 1 | N3: LIVE_REPLAY | O3: 1
A4: =Telemetry!A4 -> 2019-12-09T00:02:00Z | B4: =Telemetry!B4 -> ISS-25544 | C4: =Telemetry!V4 -> 56.241482 | D4: =MAX(0,MIN(100,100-ABS(Telemetry!Y4-20)*3)) -> 73.464227 | E4: =MAX(0,MIN(100,100-ABS(Telemetry!AA4-90)*1.2)) -> 76.478811 | F4: =IF(Telemetry!AB4="ON",95,100) -> 95 | G4: =IF(OR(Channel_Anomalies!C4=1,Channel_Anomalies!D4=1,Channel_Anomalies!E4=1),1,0) -> 0 | H4: =IF(Channel_Anomalies!C4=1,"temperature",IF(Channel_Anomalies!D4=1,"battery_voltage",IF(Channel_Anomalies!E4=1,"solar_power_input",""))) | I4: =IF(Channel_Anomalies!C4=1,0.9,IF(Channel_Anomalies!D4=1,0.85,IF(Channel_Anomalies!E4=1,0.75,0))) -> 0 | J4: =MAX(0,MIN(100,0.35*C4+0.25*D4+0.25*E4+0.15*F4-IF(G4=1,12,0))) -> 71.420278 | K4: =IF(J4<40,"CRITICAL",IF(J4<60,"HIGH",IF(J4<80,"MED","LOW"))) -> MED | L4: ="TWIN-"&TEXT(M4,"000000") -> TWIN-000002 | M4: =ROW()-2 -> 2 | N4: LIVE_REPLAY | O4: 1
A5: =Telemetry!A5 -> 2019-12-09T00:03:00Z | B5: =Telemetry!B5 -> ISS-25544 | C5: =Telemetry!V5 -> 54.775727 | D5: =MAX(0,MIN(100,100-ABS(Telemetry!Y5-20)*3)) -> 70.962475 | E5: =MAX(0,MIN(100,100-ABS(Telemetry!AA5-90)*1.2)) -> 76.427491 | F5: =IF(Telemetry!AB5="ON",95,100) -> 95 | G5: =IF(OR(Channel_Anomalies!C5=1,Channel_Anomalies!D5=1,Channel_Anomalies!E5=1),1,0) -> 0 | H5: =IF(Channel_Anomalies!C5=1,"temperature",IF(Channel_Anomalies!D5=1,"battery_voltage",IF(Channel_Anomalies!E5=1,"solar_power_input",""))) | I5: =IF(Channel_Anomalies!C5=1,0.9,IF(Channel_Anomalies!D5=1,0.85,IF(Channel_Anomalies!E5=1,0.75,0))) -> 0 | J5: =MAX(0,MIN(100,0.35*C5+0.25*D5+0.25*E5+0.15*F5-IF(G5=1,12,0))) -> 70.268996 | K5: =IF(J5<40,"CRITICAL",IF(J5<60,"HIGH",IF(J5<80,"MED","LOW"))) -> MED | L5: ="TWIN-"&TEXT(M5,"000000") -> TWIN-000003 | M5: =ROW()-2 -> 3 | N5: LIVE_REPLAY | O5: 1
A6: =Telemetry!A6 -> 2019-12-09T00:04:00Z | B6: =Telemetry!B6 -> ISS-25544 | C6: =Telemetry!V6 -> 53.313037 | D6: =MAX(0,MIN(100,100-ABS(Telemetry!Y6-20)*3)) -> 68.111798 | E6: =MAX(0,MIN(100,100-ABS(Telemetry!AA6-90)*1.2)) -> 76.250912 | F6: =IF(Telemetry!AB6="ON",95,100) -> 95 | G6: =IF(OR(Channel_Anomalies!C6=1,Channel_Anomalies!D6=1,Channel_Anomalies!E6=1),1,0) -> 0 | H6: =IF(Channel_Anomalies!C6=1,"temperature",IF(Channel_Anomalies!D6=1,"battery_voltage",IF(Channel_Anomalies!E6=1,"solar_power_input",""))) | I6: =IF(Channel_Anomalies!C6=1,0.9,IF(Channel_Anomalies!D6=1,0.85,IF(Channel_Anomalies!E6=1,0.75,0))) -> 0 | J6: =MAX(0,MIN(100,0.35*C6+0.25*D6+0.25*E6+0.15*F6-IF(G6=1,12,0))) -> 69.000241 | K6: =IF(J6<40,"CRITICAL",IF(J6<60,"HIGH",IF(J6<80,"MED","LOW"))) -> MED | L6: ="TWIN-"&TEXT(M6,"000000") -> TWIN-000004 | M6: =ROW()-2 -> 4 | N6: LIVE_REPLAY | O6: 1
A7: =Telemetry!A7 -> 2019-12-09T00:05:00Z | B7: =Telemetry!B7 -> ISS-25544 | C7: =Telemetry!V7 -> 51.878395 | D7: =MAX(0,MIN(100,100-ABS(Telemetry!Y7-20)*3)) -> 65.611226 | E7: =MAX(0,MIN(100,100-ABS(Telemetry!AA7-90)*1.2)) -> 75.527281 | F7: =IF(Telemetry!AB7="ON",95,100) -> 95 | G7: =IF(OR(Channel_Anomalies!C7=1,Channel_Anomalies!D7=1,Channel_Anomalies!E7=1),1,0) -> 0 | H7: =IF(Channel_Anomalies!C7=1,"temperature",IF(Channel_Anomalies!D7=1,"battery_voltage",IF(Channel_Anomalies!E7=1,"solar_power_input",""))) | I7: =IF(Channel_Anomalies!C7=1,0.9,IF(Channel_Anomalies!D7=1,0.85,IF(Channel_Anomalies!E7=1,0.75,0))) -> 0 | J7: =MAX(0,MIN(100,0.35*C7+0.25*D7+0.25*E7+0.15*F7-IF(G7=1,12,0))) -> 67.692065 | K7: =IF(J7<40,"CRITICAL",IF(J7<60,"HIGH",IF(J7<80,"MED","LOW"))) -> MED | L7: ="TWIN-"&TEXT(M7,"000000") -> TWIN-000005 | M7: =ROW()-2 -> 5 | N7: LIVE_REPLAY | O7: 1
A8: =Telemetry!A8 -> 2019-12-09T00:06:00Z | B8: =Telemetry!B8 -> ISS-25544 | C8: =Telemetry!V8 -> 50.427479 | D8: =MAX(0,MIN(100,100-ABS(Telemetry!Y8-20)*3)) -> 61.819224 | E8: =MAX(0,MIN(100,100-ABS(Telemetry!AA8-90)*1.2)) -> 76.387491 | F8: =IF(Telemetry!AB8="ON",95,100) -> 95 | G8: =IF(OR(Channel_Anomalies!C8=1,Channel_Anomalies!D8=1,Channel_Anomalies!E8=1),1,0) -> 0 | H8: =IF(Channel_Anomalies!C8=1,"temperature",IF(Channel_Anomalies!D8=1,"battery_voltage",IF(Channel_Anomalies!E8=1,"solar_power_input",""))) | I8: =IF(Channel_Anomalies!C8=1,0.9,IF(Channel_Anomalies!D8=1,0.85,IF(Channel_Anomalies!E8=1,0.75,0))) -> 0 | J8: =MAX(0,MIN(100,0.35*C8+0.25*D8+0.25*E8+0.15*F8-IF(G8=1,12,0))) -> 66.451296 | K8: =IF(J8<40,"CRITICAL",IF(J8<60,"HIGH",IF(J8<80,"MED","LOW"))) -> MED | L8: ="TWIN-"&TEXT(M8,"000000") -> TWIN-000006 | M8: =ROW()-2 -> 6 | N8: LIVE_REPLAY | O8: 1
A9: =Telemetry!A9 -> 2019-12-09T00:07:00Z | B9: =Telemetry!B9 -> ISS-25544 | C9: =Telemetry!V9 -> 48.971611 | D9: =MAX(0,MIN(100,100-ABS(Telemetry!Y9-20)*3)) -> 58.01368 | E9: =MAX(0,MIN(100,100-ABS(Telemetry!AA9-90)*1.2)) -> 75.857967 | F9: =IF(Telemetry!AB9="ON",95,100) -> 95 | G9: =IF(OR(Channel_Anomalies!C9=1,Channel_Anomalies!D9=1,Channel_Anomalies!E9=1),1,0) -> 0 | H9: =IF(Channel_Anomalies!C9=1,"temperature",IF(Channel_Anomalies!D9=1,"battery_voltage",IF(Channel_Anomalies!E9=1,"solar_power_input",""))) | I9: =IF(Channel_Anomalies!C9=1,0.9,IF(Channel_Anomalies!D9=1,0.85,IF(Channel_Anomalies!E9=1,0.75,0))) -> 0 | J9: =MAX(0,MIN(100,0.35*C9+0.25*D9+0.25*E9+0.15*F9-IF(G9=1,12,0))) -> 64.857976 | K9: =IF(J9<40,"CRITICAL",IF(J9<60,"HIGH",IF(J9<80,"MED","LOW"))) -> MED | L9: ="TWIN-"&TEXT(M9,"000000") -> TWIN-000007 | M9: =ROW()-2 -> 7 | N9: LIVE_REPLAY | O9: 1
A10: =Telemetry!A10 -> 2019-12-09T00:08:00Z | B10: =Telemetry!B10 -> ISS-25544 | C10: =Telemetry!V10 -> 47.839596 | D10: =MAX(0,MIN(100,100-ABS(Telemetry!Y10-20)*3)) -> 56.685174 | E10: =MAX(0,MIN(100,100-ABS(Telemetry!AA10-90)*1.2)) -> 58.057538 | F10: =IF(Telemetry!AB10="ON",95,100) -> 95 | G10: =IF(OR(Channel_Anomalies!C10=1,Channel_Anomalies!D10=1,Channel_Anomalies!E10=1),1,0) -> 0 | H10: =IF(Channel_Anomalies!C10=1,"temperature",IF(Channel_Anomalies!D10=1,"battery_voltage",IF(Channel_Anomalies!E10=1,"solar_power_input",""))) | I10: =IF(Channel_Anomalies!C10=1,0.9,IF(Channel_Anomalies!D10=1,0.85,IF(Channel_Anomalies!E10=1,0.75,0))) -> 0 | J10: =MAX(0,MIN(100,0.35*C10+0.25*D10+0.25*E10+0.15*F10-IF(G10=1,12,0))) -> 59.679537 | K10: =IF(J10<40,"CRITICAL",IF(J10<60,"HIGH",IF(J10<80,"MED","LOW"))) -> HIGH | L10: ="TWIN-"&TEXT(M10,"000000") -> TWIN-000008 | M10: =ROW()-2 -> 8 | N10: LIVE_REPLAY | O10: 1
A11: =Telemetry!A11 -> 2019-12-09T00:09:00Z | B11: =Telemetry!B11 -> ISS-25544 | C11: =Telemetry!V11 -> 46.685617 | D11: =MAX(0,MIN(100,100-ABS(Telemetry!Y11-20)*3)) -> 54.266388 | E11: =MAX(0,MIN(100,100-ABS(Telemetry!AA11-90)*1.2)) -> 58.469207 | F11: =IF(Telemetry!AB11="ON",95,100) -> 95 | G11: =IF(OR(Channel_Anomalies!C11=1,Channel_Anomalies!D11=1,Channel_Anomalies!E11=1),1,0) -> 0 | H11: =IF(Channel_Anomalies!C11=1,"temperature",IF(Channel_Anomalies!D11=1,"battery_voltage",IF(Channel_Anomalies!E11=1,"solar_power_input",""))) | I11: =IF(Channel_Anomalies!C11=1,0.9,IF(Channel_Anomalies!D11=1,0.85,IF(Channel_Anomalies!E11=1,0.75,0))) -> 0 | J11: =MAX(0,MIN(100,0.35*C11+0.25*D11+0.25*E11+0.15*F11-IF(G11=1,12,0))) -> 58.773865 | K11: =IF(J11<40,"CRITICAL",IF(J11<60,"HIGH",IF(J11<80,"MED","LOW"))) -> HIGH | L11: ="TWIN-"&TEXT(M11,"000000") -> TWIN-000009 | M11: =ROW()-2 -> 9 | N11: LIVE_REPLAY | O11: 1
A12: =Telemetry!A12 -> 2019-12-09T00:10:00Z | B12: =Telemetry!B12 -> ISS-25544 | C12: =Telemetry!V12 -> 45.563758 | D12: =MAX(0,MIN(100,100-ABS(Telemetry!Y12-20)*3)) -> 51.276813 | E12: =MAX(0,MIN(100,100-ABS(Telemetry!AA12-90)*1.2)) -> 57.16718 | F12: =IF(Telemetry!AB12="ON",95,100) -> 95 | G12: =IF(OR(Channel_Anomalies!C12=1,Channel_Anomalies!D12=1,Channel_Anomalies!E12=1),1,0) -> 0 | H12: =IF(Channel_Anomalies!C12=1,"temperature",IF(Channel_Anomalies!D12=1,"battery_voltage",IF(Channel_Anomalies!E12=1,"solar_power_input",""))) | I12: =IF(Channel_Anomalies!C12=1,0.9,IF(Channel_Anomalies!D12=1,0.85,IF(Channel_Anomalies!E12=1,0.75,0))) -> 0 | J12: =MAX(0,MIN(100,0.35*C12+0.25*D12+0.25*E12+0.15*F12-IF(G12=1,12,0))) -> 57.308314 | K12: =IF(J12<40,"CRITICAL",IF(J12<60,"HIGH",IF(J12<80,"MED","LOW"))) -> HIGH | L12: ="TWIN-"&TEXT(M12,"000000") -> TWIN-000010 | M12: =ROW()-2 -> 10 | N12: LIVE_REPLAY | O12: 1
A13: =Telemetry!A13 -> 2019-12-09T00:11:00Z | B13: =Telemetry!B13 -> ISS-25544 | C13: =Telemetry!V13 -> 44.409427 | D13: =MAX(0,MIN(100,100-ABS(Telemetry!Y13-20)*3)) -> 49.132004 | E13: =MAX(0,MIN(100,100-ABS(Telemetry!AA13-90)*1.2)) -> 59.066381 | F13: =IF(Telemetry!AB13="ON",95,100) -> 95 | G13: =IF(OR(Channel_Anomalies!C13=1,Channel_Anomalies!D13=1,Channel_Anomalies!E13=1),1,0) -> 0 | H13: =IF(Channel_Anomalies!C13=1,"temperature",IF(Channel_Anomalies!D13=1,"battery_voltage",IF(Channel_Anomalies!E13=1,"solar_power_input",""))) | I13: =IF(Channel_Anomalies!C13=1,0.9,IF(Channel_Anomalies!D13=1,0.85,IF(Channel_Anomalies!E13=1,0.75,0))) -> 0 | J13: =MAX(0,MIN(100,0.35*C13+0.25*D13+0.25*E13+0.15*F13-IF(G13=1,12,0))) -> 56.842896 | K13: =IF(J13<40,"CRITICAL",IF(J13<60,"HIGH",IF(J13<80,"MED","LOW"))) -> HIGH | L13: ="TWIN-"&TEXT(M13,"000000") -> TWIN-000011 | M13: =ROW()-2 -> 11 | N13: LIVE_REPLAY | O13: 1
... A4321: =Telemetry!A4321 -> 2019-12-11T23:59:00Z | B4321: =Telemetry!B4321 -> ISS-25544 | C4321: =Telemetry!V4321 -> 100 | D4321: =MAX(0,MIN(100,100-ABS(Telemetry!Y4321-20)*3)) -> 96.27315 | E4321: =MAX(0,MIN(100,100-ABS(Telemetry!AA4321-90)*1.2)) -> 32.892416 | F4321: =IF(Telemetry!AB4321="ON",95,100) -> 100 | G4321: =IF(OR(Channel_Anomalies!C4321=1,Channel_Anomalies!D4321=1,Channel_Anomalies!E4321=1),1,0) -> 0 | H4321: =IF(Channel_Anomalies!C4321=1,"temperature",IF(Channel_Anomalies!D4321=1,"battery_voltage",IF(Channel_Anomalies!E4321=1,"solar_power_input",""))) | I4321: =IF(Channel_Anomalies!C4321=1,0.9,IF(Channel_Anomalies!D4321=1,0.85,IF(Channel_Anomalies!E4321=1,0.75,0))) -> 0 | J4321: =MAX(0,MIN(100,0.35*C4321+0.25*D4321+0.25*E4321+0.15*F4321-IF(G4321=1,12,0))) -> 82.291391 | K4321: =IF(J4321<40,"CRITICAL",IF(J4321<60,"HIGH",IF(J4321<80,"MED","LOW"))) -> LOW | L4321: ="TWIN-"&TEXT(M4321,"000000") -> TWIN-004319 | M4321: =ROW()-2 -> 4319 | N4321: LIVE_REPLAY | O4321: 1

Sheet Legend
A1: Twin_Derived — formula assumptions
A2: Field | B2: Formula / assumption (source: COSMOS_Digital_Twin_Spec.md health engine section)
A3: battery_health | B3: Uses Telemetry battery_percentage directly (already 0-100 scale).
A4: thermal_health | B4: 100 - |temperature - 20°C| x 3, clipped 0-100. 20°C treated as ideal operating temperature; project assumption, not a datasheet spec — tune per actual subsystem thermal limits.
A5: power_health | B5: 100 - |power_draw - 90W| x 1.2, clipped 0-100. 90W treated as nominal draw baseline; project assumption — replace with your satellite's actual nominal power budget.
A6: payload_health | B6: 95 while payload is ON (reflects added system stress), 100 while OFF. Placeholder heuristic, not measured degradation.
A7: anomaly_flag / anomaly_parameter / anomaly_confidence | B7: Sourced from the per-channel is_anomaly labels already present in cosmos_channel_datasets.zip (temperature, battery_voltage, solar_power_input channels). Confidence values (0.90 / 0.85 / 0.75) are placeholder priorities by channel — replace once your anomaly detector (Advanced ML module) produces real confidence scores.
A8: health_score | B8: Weighted sum: 0.35*battery + 0.25*thermal + 0.25*power + 0.15*payload, with a flat -12 point penalty when any anomaly is flagged. Weights match the health engine formula proposed in COSMOS_Digital_Twin_Spec.md — a starting point for your prototype, meant to be tuned or replaced with ML.
A9: risk_level | B9: <40 CRITICAL · <60 HIGH · <80 MED · else LOW. Thresholds are project assumptions — align with whatever your Decision Engine module expects.
A10: twin_state_id | B10: Generated as TWIN-000000, TWIN-000001... to give every replayed row a stable ID other MISSION modules can reference.
A11: source_row_index | B11: 0-based row index into this replay dataset (row 2 = index 0), lets predict()/fork_scenario() outputs cite which real row they forked from.
A12: sync_status | B12: Fixed as "LIVE_REPLAY" for every row in this sheet, since this is the base dataset being replayed, not a forecast or scenario fork. Your app will write "FROZEN" or "SCENARIO_FORK" for twin states it generates at runtime — those aren't in this static file.
A13: state_confidence | B13: Fixed at 1.0 for every row — these are real recorded telemetry values, not predictions. predict() and fork_scenario() should output confidence < 1.0 that decays with time horizon, per the spec doc's confidence-decay concept; that logic lives in your app, not this spreadsheet.
